Workbook

Sheet DATA
A1: Site Name: 調查點名稱 | E1: Country/Island: 國家/島嶼： | G1: 台灣
A2: Transect Depth(m): 深度： | E2: Team Leader: 調查隊長：
A3: Date: 日期： | E3: Start Time: 時間：
A4: Team Scientist: 科學指導員： | E4: Temperature 水溫(ºC)： | H4: Visibility 能見度(m)：
A5: 請填寫白色格子即可
A7: Data recorded by (full names): 紀錄者中文全名：
B8: 是否分開紀錄魚類體長？ | J8: 整合數據
A9: FISH 魚類 | B9: 0-20m | C9: 25-45m | D9: 50-70m | E9: 75-95m | F9: Total總數 | G9: Mean平均 | H9: SD 標準差 | J9: FISH 魚類 | K9: 0-20m | L9: 25-45m | M9: 50-70m | N9: 75-95m | O9: Total總數 | P9: Mean平均 | Q9: SD 標準差
A10: Butterflyfish 蝴蝶魚( ≥5cm) | F10: =SUM(B10:C10:D10:E10) | G10: =AVERAGE(B10:C10:D10:E10) | H10: =STDEV(B10:C10:D10:E10) | J10: Butterflyfish 蝴蝶魚 | K10: =SUM(B10:B11) | L10: =SUM(C10:C11) | M10: =SUM(D10:D11) | N10: =SUM(E10:E11) | O10: =SUM(K10:N10) | P10: =AVERAGE(K10:N10) | Q10: =STDEV(K10:N10)
A11: Butterflyfish 蝴蝶魚( <5cm) | F11: =SUM(B11:C11:D11:E11) | G11: =AVERAGE(B11:C11:D11:E11) | H11: =STDEV(B11:C11:D11:E11) | J11: Haemulidae 石鱸 | K11: =SUM(B12:B13) | L11: =SUM(C12:C13) | M11: =SUM(D12:D13) | N11: =SUM(E12:E13) | O11: =SUM(K11:N11) | P11: =AVERAGE(K11:N11) | Q11: =STDEV(K11:N11)
A12: Haemulidae 石鱸 | F12: =SUM(B12:C12:D12:E12) | G12: =AVERAGE(B12:C12:D12:E12) | H12: =STDEV(B12:C12:D12:E12) | J12: Snapper 笛鯛 | K12: =SUM(B14:B15) | L12: =SUM(C14:C15) | M12: =SUM(D14:D15) | N12: =SUM(E14:E15) | O12: =SUM(K12:N12) | P12: =AVERAGE(K12:N12) | Q12: =STDEV(K12:N12)
A13: Haemulidae 妞妞 | F13: =SUM(B13:C13:D13:E13) | G13: =AVERAGE(B13:C13:D13:E13) | H13: =STDEV(B13:C13:D13:E13) | J13: Barramundi cod 老鼠斑 | K13: =B16 | L13: =C16 | M13: =D16 | N13: =E16 | O13: =SUM(K13:N13) | P13: =AVERAGE(K13:N13) | Q13: =STDEV(K13:N13)
A14: Snapper笛鯛( ≥20cm) | F14: =SUM(B14:C14:D14:E14) | G14: =AVERAGE(B14:C14:D14:E14) | H14: =STDEV(B14:C14:D14:E14) | J14: Grouper 石斑魚 (≥30cm) | K14: =SUM(B24:B27) | L14: =SUM(C24:C27) | M14: =SUM(D24:D27) | N14: =SUM(E24:E27) | O14: =SUM(K14:N14) | P14: =AVERAGE(K14:N14) | Q14: =STDEV(K14:N14)
A15: Snapper 小笛鯛( < 20cm) | F15: =SUM(B15:C15:D15:E15) | G15: =AVERAGE(B15:C15:D15:E15) | H15: =STDEV(B15:C15:D15:E15) | J15: Humphead wrasse 蘇眉 | K15: =B17 | L15: =C17 | M15: =D17 | N15: =E17 | O15: =SUM(K15:N15) | P15: =AVERAGE(K15:N15) | Q15: =STDEV(K15:N15)
A16: Barramundi cod 老鼠斑 | F16: =SUM(B16:C16:D16:E16) | G16: =AVERAGE(B16:C16:D16:E16) | H16: =STDEV(B16:C16:D16:E16) | J16: Bumphead parrotfish 隆頭鸚哥 | K16: =B18 | L16: =C18 | M16: =D18 | N16: =E18 | O16: =SUM(K16:N16) | P16: =AVERAGE(K16:N16) | Q16: =STDEV(K16:N16)
A17: Humphead wrasse 蘇眉 | F17: =SUM(B17:C17:D17:E17) | G17: =AVERAGE(B17:C17:D17:E17) | H17: =STDEV(B17:C17:D17:E17) | J17: Parrotfish 鸚哥魚 （≥20cm) | K17: =B19 | L17: =C19 | M17: =D19 | N17: =E19 | O17: =SUM(K17:N17) | P17: =AVERAGE(K17:N17) | Q17: =STDEV(K17:N17)
A18: Bumphead parrotfish 隆頭鸚哥 | F18: =SUM(B18:C18:D18:E18) | G18: =AVERAGE(B18:C18:D18:E18) | H18: =STDEV(B18:C18:D18:E18) | J18: Moray eel 裸胸鯙 | K18: =B21 | L18: =C21 | M18: =D21 | N18: =E21 | O18: =SUM(K18:N18) | P18: =AVERAGE(K18:N18) | Q18: =STDEV(K18:N18)
A19: Parrotfish 鸚哥魚 （≥20cm) | F19: =SUM(B19:C19:D19:E19) | G19: =AVERAGE(B19:C19:D19:E19) | H19: =STDEV(B19:C19:D19:E19)
A20: Parrotfish 鸚哥魚 （<20cm) | F20: =SUM(B20:C20:D20:E20) | G20: =AVERAGE(B20:C20:D20:E20) | H20: =STDEV(B20:C20:D20:E20)
A21: Moray eel 裸胸鯙 | F21: =SUM(B21:C21:D21:E21) | G21: =AVERAGE(B21:C21:D21:E21) | H21: =STDEV(B21:C21:D21:E21)
A23: Grouper 石斑魚 < 30cm | F23: =SUM(B23:C23:D23:E23) | G23: =AVERAGE(B23:C23:D23:E23) | H23: =STDEV(B23:C23:D23:E23)
A24: Grouper 30-40 cm | F24: =SUM(B24:C24:D24:E24) | G24: =AVERAGE(B24:C24:D24:E24) | H24: =STDEV(B24:C24:D24:E24)
A25: Grouper 40-50 cm | F25: =SUM(B25:C25:D25:E25) | G25: =AVERAGE(B25:C25:D25:E25) | H25: =STDEV(B25:C25:D25:E25)
A26: Grouper 50-60 cm | F26: =SUM(B26:C26:D26:E26) | G26: =AVERAGE(B26:C26:D26:E26) | H26: =STDEV(B26:C26:D26:E26)
A27: Grouper >60 cm | F27: =SUM(B27:C27:D27:E27) | G27: =AVERAGE(B27:C27:D27:E27) | H27: =STDEV(B27:C27:D27:E27)
A28: Grouper total 石斑魚總數 | B28: =SUM(B23:B27) | C28: =SUM(C23:C27) | D28: =SUM(D23:D27) | E28: =SUM(E23:E27) | F28: =SUM(B28:C28:D28:E28) | G28: =AVERAGE(B28:C28:D28:E28) | H28: =STDEV(B28:C28:D28:E28)
A30: Data recorded by (full names): 紀錄者中文全名：
A32: INVERTS 無脊椎類 | B32: 0-20m | C32: 25-45m | D32: 50-70m | E32: 75-95m | F32: Total | G32: Mean | H32: SD
A33: Banded coral shrimp 清潔蝦 | F33: =SUM(B33:C33:D33:E33) | G33: =AVERAGE(B33:C33:D33:E33) | H33: =STDEV(B33:C33:D33:E33)
A34: Diadema 魔鬼海膽 | F34: =SUM(B34:C34:D34:E34) | G34: =AVERAGE(B34:C34:D34:E34) | H34: =STDEV(B34:C34:D34:E34)
A35: Echinothrix 刺棘海膽 | F35: =SUM(B35:C35:D35:E35) | G35: =AVERAGE(B35:C35:D35:E35) | H35: =STDEV(B35:C35:D35:E35)
A36: Pencil urchin鉛筆海膽 | F36: =SUM(B36:C36:D36:E36) | G36: =AVERAGE(B36:C36:D36:E36) | H36: =STDEV(B36:C36:D36:E36)
A37: Collector urchin馬糞海膽 | F37: =SUM(B37:C37:D37:E37) | G37: =AVERAGE(B37:C37:D37:E37) | H37: =STDEV(B37:C37:D37:E37)
A38: Sea cucumber海參 | F38: =SUM(B38:C38:D38:E38) | G38: =AVERAGE(B38:C38:D38:E38) | H38: =STDEV(B38:C38:D38:E38)
A39: Crown-of-thorns棘冠海星 | F39: =SUM(B39:C39:D39:E39) | G39: =AVERAGE(B39:C39:D39:E39) | H39: =STDEV(B39:C39:D39:E39)
A40: Triton大法螺 | F40: =SUM(B40:C40:D40:E40) | G40: =AVERAGE(B40:C40:D40:E40) | H40: =STDEV(B40:C40:D40:E40)
A41: Lobster龍蝦 | F41: =SUM(B41:C41:D41:E41) | G41: =AVERAGE(B41:C41:D41:E41) | H41: =STDEV(B41:C41:D41:E41)
A43: Giant clam硨磲貝
A44: Giant clam <10 cm | F44: =SUM(B44:C44:D44:E44) | G44: =AVERAGE(B44:C44:D44:E44) | H44: =STDEV(B44:C44:D44:E44)
A45: Giant clam 10-20 cm | F45: =SUM(B45:C45:D45:E45) | G45: =AVERAGE(B45:C45:D45:E45) | H45: =STDEV(B45:C45:D45:E45)
...

Sheet GRAPHS
E1: PLEASE SELECT WHICH GRAPHS YOU WANT TO USE FROM THE FOLLOWING OPTIONS AND COMPLETE THE TITLE WHERE INDICATED IN BLUE.
A2: Reef Check Summary Data | E2: TO CHANGE THE TEXT TO BLACK, SELECT THE TEXT, GO TO THE TEXT COLOUR BOX IN THE FORMATTING TOOLBAR AND SELECT BLACK.
A3: DO NOT TYPE IN THE BOXES BELOW | E3: Reef Check Summary Graphs
A4: Fish | B4: Mean | C4: SE
A5: Butterflyfish | B5: =DATA!P10 | C5: =SUM(DATA!Q10/SQRT(4))
A6: Haemulidae | B6: =DATA!P11 | C6: =SUM(DATA!Q11/SQRT(4))
A7: Snapper | B7: =DATA!P12 | C7: =SUM(DATA!Q12/SQRT(4)) | E7: Reef Check Fish Graphs for <<RC reef name, depth and date>>
A8: Barramundi cod | B8: =DATA!P13 | C8: =SUM(DATA!Q13/SQRT(4))
A9: Grouper(≥30cm) | B9: =DATA!P14 | C9: =SUM(DATA!Q14/SQRT(4))
A10: Grouper(<30cm) | B10: =DATA!G23 | C10: =SUM(DATA!H23/SQRT(4))
A11: Humphead wrasse | B11: =DATA!P15 | C11: =SUM(DATA!Q15/SQRT(4))
A12: Bumphead parrot | B12: =DATA!P16 | C12: =SUM(DATA!Q16/SQRT(4))
A13: Parrotfish(≥20cm) | B13: =DATA!P17 | C13: =SUM(DATA!Q17/SQRT(4))
A14: Moray eel | B14: =DATA!P18 | C14: =SUM(DATA!Q18/SQRT(4))
A16: 選擇性紀錄，本場次是否紀錄： | B16: =DATA!E8
A17: Fish Size(cm) | B17: Mean | C17: SE
A18: 蝴蝶魚( ≥5cm) | B18: =DATA!G10 | C18: =SUM(DATA!H10/SQRT(4))
A19: 蝴蝶魚( <5cm) | B19: =DATA!G11 | C19: =SUM(DATA!H11/SQRT(4))
A20: 石鱸 | B20: =DATA!G12 | C20: =SUM(DATA!H12/SQRT(4))
A21: 妞妞 | B21: =DATA!G13 | C21: =SUM(DATA!H13/SQRT(4))
A22: 笛鯛( ≥20cm) | B22: =DATA!G14 | C22: =SUM(DATA!H14/SQRT(4))
A23: 小笛鯛( < 20cm) | B23: =DATA!G15 | C23: =SUM(DATA!H15/SQRT(4))
A24: 鸚哥魚 （≥20cm) | B24: =DATA!G19 | C24: =SUM(DATA!H19/SQRT(4))
A25: 鸚哥魚 （<20cm) | B25: =DATA!G20 | C25: =SUM(DATA!H20/SQRT(4))
A26: 石斑魚 (≥30cm) | B26: =DATA!P14 | C26: =SUM(DATA!Q14/SQRT(4))
A27: 石斑魚 (< 30cm) | B27: =DATA!G23 | C27: =SUM(DATA!H23/SQRT(4))
A34: Invertebrates | B34: Mean | C34: SE
A35: Banded coral shrimp | B35: =DATA!G33 | C35: =SUM(DATA!H33/SQRT(4))
A36: Diadema | B36: =DATA!G34 | C36: =SUM(DATA!H34/SQRT(4))
A37: Echinothrix | B37: =DATA!G35 | C37: =SUM(DATA!H35/SQRT(4))
A38: Pencil urchin | B38: =DATA!G36 | C38: =SUM(DATA!H36/SQRT(4))
A39: Collector urchin | B39: =DATA!G37 | C39: =SUM(DATA!H37/SQRT(4))
A40: Sea cucumber | B40: =DATA!G38 | C40: =SUM(DATA!H38/SQRT(4))
A41: Crown-of-thorns | B41: =DATA!G39 | C41: =SUM(DATA!H39/SQRT(4))
A42: Giant clam | B42: =DATA!G50 | C42: =SUM(DATA!H50/SQRT(4))
A43: Triton | B43: =DATA!G40 | C43: =SUM(DATA!H40/SQRT(4))
A44: Lobster | B44: =DATA!G41 | C44: =SUM(DATA!H41/SQRT(4))
A46: Giant clam (cm) | B46: Mean | C46: SE
A47: <10 | B47: =DATA!G44 | C47: =SUM(DATA!H44/SQRT(4))
A48: 10-20 | B48: =DATA!G45 | C48: =SUM(DATA!H45/SQRT(4))
...

Sheet EXPORT
A1: year | B1: month | C1: day | D1: county | E1: town | F1: site | G1: E | H1: N | I1: depth | J1: HC | K1: SC | L1: RKC | M1: NIA | N1: SP | O1: RC | P1: RB | Q1: SD | R1: SI | S1: OT | T1: comments | U1: benthos recorded by | V1: segment | W1: butterflyfish | X1: butterflyfish_less5 | Y1: sweetlips | Z1: sweetlips_juv | AA1: snapper | AB1: snapper_less20 | AC1: barramundi cod | AD1: humphead wrasse | AE1: bumphead parrotfish | AF1: otherParrotfish | AG1: otherParrotfish_less20 | AH1: moray eel | AI1: grouper_less30 | AJ1: grouper3040 | AK1: grouper4050 | AL1: grouper5060 | AM1: grouper60 | AN1: others | AO1: fish recorded by 1 | AP1: banded coral shrimp | AQ1: diadema | AR1: Echinothrix | AS1: pencil urchin | AT1: collector urchin | AU1: seacucumber | AV1: crown of thorns | AW1: triton | AX1: lobster | AY1: giantclam_less10 | AZ1: giantclam1020 | BA1: giantclam2030 | BB1: giantclam3040 | BC1: giantclam4050 | BD1: giantclam50 | BE1: boat anchor | BF1: dynamite | BG1: other coral damage | BH1: fishnet trash | BI1: general trash | BJ1: bleaching%population | BK1: bleaching%colony | BL1: disease%coral black band | BM1: disease%coral white band | BN1: sharks | BO1: turtles | BP1: mantas | BQ1: other | BR1: comments | BS1: invert recorded by
A2: =YEAR(DATA!B3) | B2: =MONTH(DATA!$B$3) | C2: =DAY(DATA!$B$3) | F2: =DATA!B$1 | I2: =DATA!B2 | W2: =DATA!B10 | X2: =DATA!B11 | Y2: =DATA!B12 | Z2: =DATA!B13 | AA2: =DATA!B14 | AB2: =DATA!B15 | AC2: =DATA!B16 | AD2: =DATA!B17 | AE2: =DATA!B18 | AF2: =DATA!B19 | AG2: =DATA!B20 | AH2: =DATA!B21 | AI2: =DATA!B23 | AJ2: =DATA!B24 | AK2: =DATA!B25 | AL2: =DATA!B26 | AM2: =DATA!B27 | AO2: =DATA!$B$7&"、"&DATA!$E$7 | AP2: =DATA!B33 | AQ2: =DATA!B34 | AR2: =DATA!B35 | AS2: =DATA!B36 | AT2: =DATA!B37 | AU2: =DATA!B38 | AV2: =DATA!B39 | AW2: =DATA!B40 | AX2: =DATA!B41 | AY2: =DATA!B44 | AZ2: =DATA!B45 | BA2: =DATA!B46 | BB2: =DATA!B47 | BC2: =DATA!B48 | BD2: =DATA!B49 | BE2: =DATA!K55 | BF2: =DATA!K56 | BG2: =DATA!K57 | BH2: =DATA!K58 | BI2: =DATA!K59 | BJ2: =DATA!B68 | BK2: =DATA!B69 | BL2: =DATA!B71 | BM2: =DATA!B72 | BN2: =DATA!B61 | BO2: =DATA!B62 | BP2: =DATA!B63 | BQ2: =DATA!B64 | BR2: =DATA!B66 | BS2: =DATA!$B$30&"、"&DATA!$E$30
A3: =YEAR(DATA!B3) | B3: =MONTH(DATA!$B$3) | C3: =DAY(DATA!$B$3) | F3: =DATA!B$1 | I3: =DATA!B2 | W3: =DATA!C10 | X3: =DATA!C11 | Y3: =DATA!C12 | Z3: =DATA!C13 | AA3: =DATA!C14 | AB3: =DATA!C15 | AC3: =DATA!C16 | AD3: =DATA!C17 | AE3: =DATA!C18 | AF3: =DATA!C19 | AG3: =DATA!C20 | AH3: =DATA!C21 | AI3: =DATA!C23 | AJ3: =DATA!C24 | AK3: =DATA!C25 | AL3: =DATA!C26 | AM3: =DATA!C27 | AO3: =DATA!$B$7&"、"&DATA!$E$7 | AP3: =DATA!C33 | AQ3: =DATA!C34 | AR3: =DATA!C35 | AS3: =DATA!C36 | AT3: =DATA!C37 | AU3: =DATA!C38 | AV3: =DATA!C39 | AW3: =DATA!C40 | AX3: =DATA!C41 | AY3: =DATA!C44 | AZ3: =DATA!C45 | BA3: =DATA!C46 | BB3: =DATA!C47 | BC3: =DATA!C48 | BD3: =DATA!C49 | BE3: =DATA!L55 | BF3: =DATA!L56 | BG3: =DATA!L57 | BH3: =DATA!L58 | BI3: =DATA!L59 | BJ3: =DATA!C68 | BK3: =DATA!C69 | BL3: =DATA!C71 | BM3: =DATA!C72 | BN3: =DATA!C61 | BO3: =DATA!C62 | BP3: =DATA!C63 | BQ3: =DATA!C64 | BR3: =DATA!B66 | BS3: =DATA!$B$30&"、"&DATA!$E$30
A4: =YEAR(DATA!B3) | B4: =MONTH(DATA!$B$3) | C4: =DAY(DATA!$B$3) | F4: =DATA!B$1 | I4: =DATA!B2 | W4: =DATA!D10 | X4: =DATA!D11 | Y4: =DATA!D12 | Z4: =DATA!D13 | AA4: =DATA!D14 | AB4: =DATA!D15 | AC4: =DATA!D16 | AD4: =DATA!D17 | AE4: =DATA!D18 | AF4: =DATA!D19 | AG4: =DATA!D20 | AH4: =DATA!D21 | AI4: =DATA!D23 | AJ4: =DATA!D24 | AK4: =DATA!D25 | AL4: =DATA!D26 | AM4: =DATA!D27 | AO4: =DATA!$B$7&"、"&DATA!$E$7 | AP4: =DATA!D33 | AQ4: =DATA!D34 | AR4: =DATA!D35 | AS4: =DATA!D36 | AT4: =DATA!D37 | AU4: =DATA!D38 | AV4: =DATA!D39 | AW4: =DATA!D40 | AX4: =DATA!D41 | AY4: =DATA!D44 | AZ4: =DATA!D45 | BA4: =DATA!D46 | BB4: =DATA!D47 | BC4: =DATA!D48 | BD4: =DATA!D49 | BE4: =DATA!M55 | BF4: =DATA!M56 | BG4: =DATA!M57 | BH4: =DATA!M58 | BI4: =DATA!M59 | BJ4: =DATA!D68 | BK4: =DATA!D69 | BL4: =DATA!D71 | BM4: =DATA!D72 | BN4: =DATA!D61 | BO4: =DATA!D62 | BP4: =DATA!D63 | BQ4: =DATA!D64 | BR4: =DATA!B66 | BS4: =DATA!$B$30&"、"&DATA!$E$30
A5: =YEAR(DATA!B3) | B5: =MONTH(DATA!$B$3) | C5: =DAY(DATA!$B$3) | F5: =DATA!B$1 | I5: =DATA!B2 | W5: =DATA!E10 | X5: =DATA!E11 | Y5: =DATA!E12 | Z5: =DATA!E13 | AA5: =DATA!E14 | AB5: =DATA!E15 | AC5: =DATA!E16 | AD5: =DATA!E17 | AE5: =DATA!E18 | AF5: =DATA!E19 | AG5: =DATA!E20 | AH5: =DATA!E21 | AI5: =DATA!E23 | AJ5: =DATA!E24 | AK5: =DATA!E25 | AL5: =DATA!E26 | AM5: =DATA!E27 | AO5: =DATA!$B$7&"、"&DATA!$E$7 | AP5: =DATA!E33 | AQ5: =DATA!E34 | AR5: =DATA!E35 | AS5: =DATA!E36 | AT5: =DATA!E37 | AU5: =DATA!E38 | AV5: =DATA!E39 | AW5: =DATA!E40 | AX5: =DATA!E41 | AY5: =DATA!E44 | AZ5: =DATA!E45 | BA5: =DATA!E46 | BB5: =DATA!E47 | BC5: =DATA!E48 | BD5: =DATA!E49 | BE5: =DATA!N55 | BF5: =DATA!N56 | BG5: =DATA!N57 | BH5: =DATA!N58 | BI5: =DATA!N59 | BJ5: =DATA!E68 | BK5: =DATA!E69 | BL5: =DATA!E71 | BM5: =DATA!E72 | BN5: =DATA!E61 | BO5: =DATA!E62 | BP5: =DATA!E63 | BQ5: =DATA!E64 | BR5: =DATA!B66 | BS5: =DATA!$B$30&"、"&DATA!$E$30

Sheet INSTRUCTIONS
A1: HOW TO USE THE DATA SHEET
A2: 1. Enter your data into the white boxes on the DATA worksheet. You will find that you can't type anywhere else because the rest of the sheet is locked.
A4: 2. Use the substrate codes provided but ensure there is no space after the code letters or the computer program will not recognize the code. Only enter one code per box.
A6: Please check you have entered the data correctly
A7: 3. For each transect segment, check that the total columns add up to 40. This is colored in red for you.
A9: 4. Also double check that all of the codes were entered in correctly from the spreadsheet.
A11: What happens if the segment totals are less than 40?
A12: 5. You may have entered in a code wrong - first check this. If all the codes look right, you may have put a space after the code letters.
A15: HOW TO ANALYZE THE DATA
A16: 1. As you enter your data, graphs are produced simultaneously and automatically on the GRAPHS worksheet.
A18: 2. All you have to do is enter the site name, date and depth of the survey by replacing the words in blue on the graph title. You can then change the blue writing to black by selecting the text and using the text color button in the formatting toolbar.
A20: 3. The graphs page is ready to print, or you can select the graphs you want and copy them into a Word document.
... A54: For general stats, "Experimental Design and Data Analysis for Biologists", by G. P. Quinn and M. J. Keough, 2002, Cambridge University Press.

Sheet FIELD SHEET FISH
A1: Site Name: | E1: Country/Island:
A2: Transect Depth: | E2: Team Leader:
A3: Date: | E3: Start Time:
A4: Data recorded by (full names):
C6: 0-20m | D6: 25-45m | E6: 50-70m | F6: 75-95m
A7: Butterflyfish Family Chaetodontidae
A8: Grunts/Sweetlips/Margates Family Haemulidae
A9: Snapper Family Lutjanidae
A10: Barramundi cod Cromileptes altivelis
A11: Humphead (Napoleon) wrasse Cheilinus undulatus
A12: Bumphead parrotfish Bolbometopon muricatum
A13: Other parrotfish ONLY >20cm Family Scaridae
A14: Moray eel Family Muraenidae
A16: Grouper ONLY >30cm Family Serranidae | C16: 0-20m | D16: 25-45m | E16: 50-70m | F16: 75-95m
A17: 30-40 cm
A18: 40-50 cm
A19: 50-60 cm
A20: >60 cm
A22: Rare animals sighted (#/type/size) | C22: 0-20m | D22: 25-45m | E22: 50-70m | F22: 75-95m
A23: Sharks
A24: Turtles
A25: Mantas
A26: Other
A27: Comments:
A29: This page is ready to print.

Sheet FIELD SHEET INVERTS
C1: Site Name: | G1: Country/Island:
C2: Transect Depth: | G2: Team Leader:
C3: Date: | G3: Start Time:
C4: Data recorded by (full names):
C6: Invertebrates | E6: 0-20m | F6: 25-45m | G6: 50-70m | H6: 75-95m
C7: Banded coral shrimp Stenopus hispidus
C8: Long-spined black sea urchin Diadema and Echinothrix spp.
C9: Pencil urchin Heterocentrotus mammillatus
C10: Collector urchin Tripneustes spp.
C11: Sea cucumber (only 3 RC species) Family Holothuriidae
C12: Crown-of-thorns starfish Acanthaster planci
C13: Triton Charonia tritonis
C14: Lobster (spiny and slipper/rock) Malacostraca (Decapoda)
C16: Giant clam (Tridacna spp.) | E16: 0-20m | F16: 25-45m | G16: 50-70m | H16: 75-95m
C17: <10 cm
C18: 10-20 cm
C19: 20-30 cm
C20: 30-40 cm
C21: 40-50 cm
C22: >50 cm
C24: Impacts: Coral Damage/Disease/ Bleaching/Trash | E24: 0 = none, 1 = low (1 piece), 2 = medium (2-4 pieces) and 3 = high (5+ pieces)
E25: 0-20m | F25: 25-45m | G25: 50-70m | H25: 75-95m
C26: Coral damage: Boat/Anchor
C27: Coral damage: Dynamite
C28: Coral damage: Other
C29: Trash: Fish nets
C30: Trash: General
C31: Bleaching (% of coral population)* | E31: % | F31: % | G31: % | H31: %
C32: Bleaching (% of coral colony) | E32: % | F32: % | G32: % | H32: %
C33: Coral Disease (estimate % of colonies affected) | D33: Black Band | E33: % | F33: % | G33: % | H33: %
D34: White Band | E34: % | F34: % | G34: % | H34: %
C35: Rare animals sighted (#/type/size) | E35: 0-20m | F35: 25-45m | G35: 50-70m | H35: 75-95m
C36: Sharks
C37: Turtles
C38: Mantas
C39: Other
C40: Comments:
C42: *If you have estimated the % of bleached HC on your substrate sheet (LINE 37), copy the numbers into the Bleaching (% of coral population) field
C44: This page is ready to print.

Sheet siteName
A1: 樣點名稱 | B1: Site Name
A2: 野柳 | B2: Yeliu
A3: 潮境保育區 | B3: Chaojing protected area
A4: 番仔澳 | B4: FanCai'ao
A5: 鼻頭角 | B5: Bitoujiao
A6: 龍洞1.5號 | B6: Longdong 1.5
A7: 龍洞4號-北 | B7: Longdong 4 North
A8: 龍洞4號-南 | B8: Longdong 4 South
A9: 和平島 | B9: Heping Island
A10: 合界 | B10: Hejie
A11: 後壁湖 | B11: Houbihu
A12: 石梯坪 | B12: Shitiping
... A42: 曙光礁 | B42: Shuguang Reef
