Workbook
Name seg_1: DATA!$B$15:$B$34,DATA!$D$15:$D$34
Name seg_2: DATA!$F$15:$F$34,DATA!$H$15:$H$34
Name seg_3: DATA!$J$15:$J$34,DATA!$L$15:$L$34
Name seg_4: DATA!$N$15:$N$34,DATA!$P$15:$P$34

Sheet DATA
A1: Site name: 調查點名稱： | H1: Country/Island: 國家/島嶼： | K1: 台灣 | Q1: 請輸入 | R1: 底質類別 | S1: 底質類別縮寫
A2: Depth(m): 深度： | H2: Date: 日期： | Q2: 1 | R2: 硬珊瑚 | S2: HC
A3: TS/TL: 調查隊長： | H3: Data recorded by: 紀錄者中文全名： | Q3: 2 | R3: 軟珊瑚 | S3: SC
A4: Time:(24h) 時間 | H4: Visibility 能見度(m)： | Q4: 3 | R4: 新死珊瑚 | S4: RKC
A5: 是否紀錄硬珊瑚型態 | H5: Temperature 水溫(ºC)： | Q5: 4 | R5: 藻類 | S5: NIA
A6: 重大珊瑚 損害性颱風 | H6: Air Temperature 氣溫(ºC)： | Q6: 5 | R6: 海綿 | S6: SP
A7: 緯度(Latitude) | H7: 經度(Longitude) | Q7: 6 | R7: 岩石 | S7: RC
A8: 天氣(weather) | Q8: 7 | R8: 碎石 | S8: RB
Q9: 8 | R9: 沙 | S9: SD
Q10: 9 | R10: 泥沙 | S10: SI
A11: 請依照右側對照表，輸入Q欄代號 | Q11: 0 | R11: 其他 | S11: OT
A12: (For first segment, if start point is 0 m, last point is 19.5 m) | Q12: a | R12: 硬珊瑚-a | S12: HC-a
A13: SEGMENT 1 | E13: SEGMENT 2 | I13: SEGMENT 3 | M13: SEGMENT 4 | Q13: b | R13: 硬珊瑚-b | S13: HC-b
A14: 0 - 19.5 m | E14: 25 - 44.5 m | I14: 50 - 69.5 m | M14: 75 - 94.5 m | Q14: c | R14: 硬珊瑚-c | S14: HC-c
A15: 0 | C15: 10 | E15: 25 | G15: 35 | I15: 50 | K15: 60 | M15: 75 | O15: 85 | Q15: 91 | R15: 泥沙(硬珊瑚) | S15: SI(HC)
A16: 0.5 | C16: 10.5 | E16: 25.5 | G16: 35.5 | I16: 50.5 | K16: 60.5 | M16: 75.5 | O16: 85.5 | Q16: 92 | R16: 泥沙(軟珊瑚) | S16: SI(SC)
A17: 1 | C17: 11 | E17: 26 | G17: 36 | I17: 51 | K17: 61 | M17: 76 | O17: 86 | Q17: 93 | R17: 泥沙(新死珊瑚) | S17: SI(RKC)
A18: 1.5 | C18: 11.5 | E18: 26.5 | G18: 36.5 | I18: 51.5 | K18: 61.5 | M18: 76.5 | O18: 86.5 | Q18: 94 | R18: 泥沙(藻類) | S18: SI(NIA)
A19: 2 | C19: 12 | E19: 27 | G19: 37 | I19: 52 | K19: 62 | M19: 77 | O19: 87 | Q19: 95 | R19: 泥砂（海綿） | S19: SI(SP)
A20: 2.5 | C20: 12.5 | E20: 27.5 | G20: 37.5 | I20: 52.5 | K20: 62.5 | M20: 77.5 | O20: 87.5 | Q20: 96 | R20: 泥沙(岩石) | S20: SI(RC)
A21: 3 | C21: 13 | E21: 28 | G21: 38 | I21: 53 | K21: 63 | M21: 78 | O21: 88 | Q21: 97 | R21: 泥沙(碎石) | S21: SI(RB)
A22: 3.5 | C22: 13.5 | E22: 28.5 | G22: 38.5 | I22: 53.5 | K22: 63.5 | M22: 78.5 | O22: 88.5 | Q22: 98 | R22: 泥沙(沙) | S22: SI(SD)
A23: 4 | C23: 14 | E23: 29 | G23: 39 | I23: 54 | K23: 64 | M23: 79 | O23: 89
A24: 4.5 | C24: 14.5 | E24: 29.5 | G24: 39.5 | I24: 54.5 | K24: 64.5 | M24: 79.5 | O24: 89.5
A25: 5 | C25: 15 | E25: 30 | G25: 40 | I25: 55 | K25: 65 | M25: 80 | O25: 90
A26: 5.5 | C26: 15.5 | E26: 30.5 | G26: 40.5 | I26: 55.5 | K26: 65.5 | M26: 80.5 | O26: 90.5
A27: 6 | C27: 16 | E27: 31 | G27: 41 | I27: 56 | K27: 66 | M27: 81 | O27: 91
A28: 6.5 | C28: 16.5 | E28: 31.5 | G28: 41.5 | I28: 56.5 | K28: 66.5 | M28: 81.5 | O28: 91.5
A29: 7 | C29: 17 | E29: 32 | G29: 42 | I29: 57 | K29: 67 | M29: 82 | O29: 92
A30: 7.5 | C30: 17.5 | E30: 32.5 | G30: 42.5 | I30: 57.5 | K30: 67.5 | M30: 82.5 | O30: 92.5
A31: 8 | C31: 18 | E31: 33 | G31: 43 | I31: 58 | K31: 68 | M31: 83 | O31: 93
A32: 8.5 | C32: 18.5 | E32: 33.5 | G32: 43.5 | I32: 58.5 | K32: 68.5 | M32: 83.5 | O32: 93.5
A33: 9 | C33: 19 | E33: 34 | G33: 44 | I33: 59 | K33: 69 | M33: 84 | O33: 94
A34: 9.5 | C34: 19.5 | E34: 34.5 | G34: 44.5 | I34: 59.5 | K34: 69.5 | M34: 84.5 | O34: 94.5
A35: 白化/疾病 珊瑚點數 # of Coral with bleaching/disease by point
C36: S1 | D36: S2 | E36: S3 | F36: S4 | G36: Total | I36: Mean | K36: SD
A37: HC白化 | G37: =SUM(C37,D37,E37,F37) | I37: =AVERAGE(C37,D37,E37,F37) | K37: =_xlfn.STDEV.S(C37,D37,E37,F37)
A38: SC白化 | G38: =SUM(C38,D38,E38,F38) | I38: =AVERAGE(C38,D38,E38,F38) | K38: =_xlfn.STDEV.S(C38,D38,E38,F38)
A39: 珊瑚疾病 （科導紀錄） | G39: =SUM(C39,D39,E39,F39) | I39: =AVERAGE(C39,D39,E39,F39) | K39: =_xlfn.STDEV.S(C39,D39,E39,F39)
A41: 若平均新死珊瑚覆蓋率 > 10% ，造成的原因可能是
...

Sheet GRAPHS
E1: PLEASE SELECT WHICH GRAPHS YOU WANT TO USE FROM THE FOLLOWING OPTIONS AND COMPLETE THE TITLE WHERE INDICATED IN BLUE.
A2: Reef Check Summary Data | E2: TO CHANGE THE TEXT TO BLACK, SELECT THE TEXT, GO TO THE TEXT COLOUR BOX IN THE FORMATTING TOOLBAR AND SELECT BLACK.
A3: DO NOT TYPE IN THE BOXES BELOW | E3: Reef Check Summary Graphs
B4: % | C4: SE
A5: HC | B5: =(DATA!J73/160)*100 | C5: =(SUM(DATA!O73/SQRT(4)))/40*100
A6: SC | B6: =(DATA!J74/160)*100 | C6: =(SUM(DATA!O74/SQRT(4)))/40*100 | E6: Mean Percent cover of Substrate for <<RC reef name, depth and date>>
A7: RKC | B7: =(DATA!J75/160)*100 | C7: =(SUM(DATA!O75/SQRT(4)))/40*100
A8: NIA | B8: =(DATA!J76/160)*100 | C8: =(SUM(DATA!O76/SQRT(4)))/40*100
A9: SP | B9: =(DATA!J77/160)*100 | C9: =(SUM(DATA!O77/SQRT(4)))/40*100
A10: RC | B10: =(DATA!J78/160)*100 | C10: =(SUM(DATA!O78/SQRT(4)))/40*100
A11: RB | B11: =(DATA!J79/160)*100 | C11: =(SUM(DATA!O79/SQRT(4)))/40*100
A12: SD | B12: =(DATA!J80/160)*100 | C12: =(SUM(DATA!O80/SQRT(4)))/40*100
A13: SI | B13: =(DATA!J81/160)*100 | C13: =(SUM(DATA!O81/SQRT(4)))/40*100
A14: OT | B14: =(DATA!J82/160)*100 | C14: =(SUM(DATA!O82/SQRT(4)))/40*100
A16: Check the Total = 100 | B16: =SUM(B5:B14)
A19: Live reef cover | B19: % | C19: SE
A20: HC | B20: =B5 | C20: =C5
A21: SC | B21: =B6 | C21: =C6
A22: NIA | B22: =B8 | C22: =C8
A23: SP | B23: =B9 | C23: =C9
A24: OT | B24: =B14 | C24: =C14
A28: Non-living reef cover | B28: % | C28: SE
A29: RKC | B29: =B7 | C29: =C7
A30: RC | B30: =B10 | C30: =C10
A31: RB | B31: =B11 | C31: =C11
A32: SD | B32: =B12 | C32: =C12
A33: SI | B33: =B13 | C33: =C13
B38: Normal | C38: Bleaching
A39: HC | B39: =(DATA!R42-DATA!G37)/DATA!R42 | C39: =DATA!G37/DATA!R42
A40: SC | B40: =(DATA!R43-DATA!G38)/DATA!R43 | C40: =DATA!G38/DATA!R43

Sheet GRAPHS_SI
E1: PLEASE SELECT WHICH GRAPHS YOU WANT TO USE FROM THE FOLLOWING OPTIONS AND COMPLETE THE TITLE WHERE INDICATED IN BLUE.
A2: Reef Check Summary Data | E2: TO CHANGE THE TEXT TO BLACK, SELECT THE TEXT, GO TO THE TEXT COLOUR BOX IN THE FORMATTING TOOLBAR AND SELECT BLACK.
A3: DO NOT TYPE IN THE BOXES BELOW | E3: Reef Check Summary Graphs
B4: % | C4: SE
A5: HC | B5: =(DATA!J47/160)*100 | C5: =(SUM(DATA!O47/SQRT(4)))/40*100
A6: SC | B6: =(DATA!J48/160)*100 | C6: =(SUM(DATA!O48/SQRT(4)))/40*100 | E6: Mean Percent cover of Substrate for <<RC reef name, depth and date>>
A7: RKC | B7: =(DATA!J49/160)*100 | C7: =(SUM(DATA!O49/SQRT(4)))/40*100
A8: NIA | B8: =(DATA!J50/160)*100 | C8: =(SUM(DATA!O50/SQRT(4)))/40*100
A9: SP | B9: =(DATA!J51/160)*100 | C9: =(SUM(DATA!O51/SQRT(4)))/40*100
A10: RC | B10: =(DATA!J52/160)*100 | C10: =(SUM(DATA!O52/SQRT(4)))/40*100
A11: RB | B11: =(DATA!J53/160)*100 | C11: =(SUM(DATA!O53/SQRT(4)))/40*100
A12: SD | B12: =(DATA!J54/160)*100 | C12: =(SUM(DATA!O54/SQRT(4)))/40*100
A13: SI | B13: =(DATA!J55/160)*100 | C13: =(SUM(DATA!O55/SQRT(4)))/40*100
A14: OT | B14: =(DATA!J56/160)*100 | C14: =(SUM(DATA!O56/SQRT(4)))/40*100
A15: HC-a | B15: =(DATA!J57/160)*100 | C15: =(SUM(DATA!O57/SQRT(4)))/40*100
A16: HC-b | B16: =(DATA!J58/160)*100 | C16: =(SUM(DATA!O58/SQRT(4)))/40*100
A17: HC-c | B17: =(DATA!J59/160)*100 | C17: =(SUM(DATA!O59/SQRT(4)))/40*100
A18: SI(HC) | B18: =(DATA!J60/160)*100 | C18: =(SUM(DATA!O60/SQRT(4)))/40*100
... A25: SI(SD) | B25: =(DATA!J67/160)*100 | C25: =(SUM(DATA!O67/SQRT(4)))/40*100
A27: Check the Total = 100 | B27: =SUM(B5:B25)
A30: reef type cover | B30: % | C30: SE
A31: HC-a | B31: =B15 | C31: =C15
A32: HC-b | B32: =B16 | C32: =C16
A33: HC-c | B33: =B17 | C33: =C17

Sheet EXPORT
A1: year | B1: month | C1: day | D1: site_en | E1: site | F1: E | G1: N | H1: depth | I1: HC | J1: SC | K1: RKC | L1: NIA | M1: SP | N1: RC | O1: RB | P1: SD | Q1: SI | R1: OT | S1: comments | T1: benthos recorded by | U1: segment | V1: butterflyfish | W1: sweetlips | X1: snapper | Y1: barramundi cod | Z1: humphead wrasse | AA1: bumphead parrotfish | AB1: other parrotfish | AC1: moray eel | AD1: grouper3040 | AE1: grouper4050 | AF1: grouper5060 | AG1: grouper60 | AH1: others | AI1: fish recorded by 1 | AJ1: banded coral shrimp | AK1: diadema | AL1: pencil urchin | AM1: collector urchin | AN1: seacucumber | AO1: crown of thorns | AP1: triton | AQ1: lobster | AR1: giantclam<10 | AS1: giantclam1020 | AT1: giantclam2030 | AU1: giantclam3040 | AV1: giantclam4050 | AW1: giantclam50 | AX1: boat anchor | AY1: dynamite | AZ1: other coral damage | BA1: fishnet trash | BB1: general trash | BC1: bleaching%population | BD1: bleaching%colony | BE1: disease%coral black band | BF1: disease%coral white band | BG1: sharks | BH1: turtles | BI1: mantas | BJ1: other | BK1: comments | BL1: invert recorded by
A2: =YEAR(DATA!$K$2) | B2: =MONTH(DATA!$K$2) | C2: =DAY(DATA!$K$2) | E2: =DATA!$C$1 | F2: =DATA!$L$7 | G2: =DATA!$C$7 | H2: =DATA!$C$2 | I2: =DATA!B73/DATA!$B$83 | J2: =DATA!B74/DATA!$B$83 | K2: =DATA!B75/DATA!$B$83 | L2: =DATA!B76/DATA!$B$83 | M2: =DATA!B77/DATA!$B$83 | N2: =DATA!B78/DATA!$B$83 | O2: =DATA!B79/DATA!$B$83 | P2: =DATA!B80/DATA!$B$83 | Q2: =DATA!B81/DATA!$B$83 | R2: =DATA!B82/DATA!$B$83 | S2: =DATA!C42 | T2: =DATA!$L$3 &"、"& DATA!$N$3
A3: =YEAR(DATA!$K$2) | B3: =MONTH(DATA!$K$2) | C3: =DAY(DATA!$K$2) | E3: =DATA!$C$1 | F3: =DATA!$L$7 | G3: =DATA!$C$7 | H3: =DATA!$C$2 | I3: =DATA!D73/DATA!$D$83 | J3: =DATA!D74/DATA!$D$83 | K3: =DATA!D75/DATA!$D$83 | L3: =DATA!D76/DATA!$D$83 | M3: =DATA!D77/DATA!$D$83 | N3: =DATA!D78/DATA!$D$83 | O3: =DATA!D79/DATA!$D$83 | P3: =DATA!D80/DATA!$D$83 | Q3: =DATA!D81/DATA!$D$83 | R3: =DATA!D82/DATA!$D$83 | T3: =DATA!$L$3 &"、"& DATA!$N$3
A4: =YEAR(DATA!$K$2) | B4: =MONTH(DATA!$K$2) | C4: =DAY(DATA!$K$2) | E4: =DATA!$C$1 | F4: =DATA!$L$7 | G4: =DATA!$C$7 | H4: =DATA!$C$2 | I4: =DATA!F73/DATA!$F$83 | J4: =DATA!F74/DATA!$F$83 | K4: =DATA!F75/DATA!$F$83 | L4: =DATA!F76/DATA!$F$83 | M4: =DATA!F77/DATA!$F$83 | N4: =DATA!F78/DATA!$F$83 | O4: =DATA!F79/DATA!$F$83 | P4: =DATA!F80/DATA!$F$83 | Q4: =DATA!F81/DATA!$F$83 | R4: =DATA!F82/DATA!$F$83 | T4: =DATA!$L$3 &"、"& DATA!$N$3
A5: =YEAR(DATA!$K$2) | B5: =MONTH(DATA!$K$2) | C5: =DAY(DATA!$K$2) | E5: =DATA!$C$1 | F5: =DATA!$L$7 | G5: =DATA!$C$7 | H5: =DATA!$C$2 | I5: =DATA!H73/DATA!$H$83 | J5: =DATA!H74/DATA!$H$83 | K5: =DATA!H75/DATA!$H$83 | L5: =DATA!H76/DATA!$H$83 | M5: =DATA!H77/DATA!$H$83 | N5: =DATA!H78/DATA!$H$83 | O5: =DATA!H79/DATA!$H$83 | P5: =DATA!H80/DATA!$H$83 | Q5: =DATA!H81/DATA!$H$83 | R5: =DATA!H82/DATA!$H$83 | T5: =DATA!$L$3 &"、"& DATA!$N$3
A16: 暫時先一起輸出，之後思考如何呈現
A17: segment | B17: ifRKC_10 | C17: ifRKC_10_other | D17: HC-a | E17: HC-b | F17: HC-c | G17: SI(HC) | H17: SI(SC) | I17: SI(RKC) | J17: SI(NIA) | K17: SI(SP) | L17: SI(RC) | M17: SI(RB) | N17: SI(SD) | O17: bleach_hc | P17: bleach_sc | Q17: coral_disease
B18: =DATA!I41 | C18: =DATA!L41 | D18: =DATA!B57/DATA!$B$68 | E18: =DATA!B58/DATA!$B$68 | F18: =DATA!B59/DATA!$B$68 | G18: =DATA!B60/DATA!$B$68 | H18: =DATA!B61/DATA!$B$68 | I18: =DATA!B62/DATA!$B$68 | J18: =DATA!B63/DATA!$B$68 | K18: =DATA!B64/DATA!$B$68 | L18: =DATA!B65/DATA!$B$68 | M18: =DATA!B66/DATA!$B$68 | N18: =DATA!B67/DATA!$B$68 | O18: =IFERROR(DATA!C37/DATA!B73,0) | P18: =IFERROR(DATA!C38/DATA!B74,0) | Q18: =IFERROR(DATA!C39/DATA!B73,0)
D19: =DATA!B58/DATA!$B$68 | E19: =DATA!B59/DATA!$B$68 | F19: =DATA!B60/DATA!$B$68 | G19: =DATA!B61/DATA!$B$68 | H19: =DATA!B62/DATA!$B$68 | I19: =DATA!B63/DATA!$B$68 | J19: =DATA!B64/DATA!$B$68 | K19: =DATA!B65/DATA!$B$68 | L19: =DATA!B66/DATA!$B$68 | M19: =DATA!B67/DATA!$B$68 | N19: =DATA!B68/DATA!$B$68 | O19: =IFERROR(DATA!D37/DATA!D73,0) | P19: =IFERROR(DATA!D38/DATA!D74, 0) | Q19: =IFERROR(DATA!D39/DATA!D73,0)
D20: =DATA!F57/DATA!$F$68 | E20: =DATA!F58/DATA!$F$68 | F20: =DATA!F59/DATA!$F$68 | G20: =DATA!F60/DATA!$F$68 | H20: =DATA!F61/DATA!$F$68 | I20: =DATA!F62/DATA!$F$68 | J20: =DATA!F63/DATA!$F$68 | K20: =DATA!F64/DATA!$F$68 | L20: =DATA!F65/DATA!$F$68 | M20: =DATA!F66/DATA!$F$68 | N20: =DATA!F67/DATA!$F$68 | O20: =IFERROR(DATA!E37/DATA!F73,0) | P20: =IFERROR(DATA!E38/DATA!F74,0) | Q20: =IFERROR(DATA!E39/DATA!F73,0)
D21: =DATA!H57/DATA!$H$68 | E21: =DATA!H58/DATA!$H$68 | F21: =DATA!H59/DATA!$H$68 | G21: =DATA!H60/DATA!$H$68 | H21: =DATA!H61/DATA!$H$68 | I21: =DATA!H62/DATA!$H$68 | J21: =DATA!H63/DATA!$H$68 | K21: =DATA!H64/DATA!$H$68 | L21: =DATA!H65/DATA!$H$68 | M21: =DATA!H66/DATA!$H$68 | N21: =DATA!H67/DATA!$H$68 | O21: =IFERROR(DATA!F37/DATA!H73,0) | P21: =IFERROR(DATA!F38/DATA!H74,0) | Q21: =IFERROR(DATA!F39/DATA!H73,0)
A27: time | B27: visibility | C27: seaTemp | D27: airTemp | E27: isCoralType | F27: isStorm | G27: weather
A28: =TEXT(DATA!C4, "HH:mm") | B28: =DATA!L4 | C28: =DATA!L5 | D28: =DATA!L6 | E28: =DATA!C5 | F28: =DATA!C6 | G28: =DATA!C8
A41: to RC foundation | C41: =IF(OR(DATA!B68<>40, DATA!D68<>40, DATA!F68<>40, DATA!H68<>40), "🚨 資料有誤，請檢查 DATA 頁！", "🆗 資料正確")
A42: SEGMENT 1段 | E42: SEGMENT 2段 | I42: SEGMENT 3段 | M42: SEGMENT 4段 | Q42: 代碼 | R42: 縮寫
A43: 0 - 19.5 m | E43: 25 - 44.5 m | I43: 50 - 69.5 m | M43: 75 - 94.5 m | Q43: 1 | R43: HC
A44: 0 | B44: =INDEX($R$43:$R$63,MATCH(DATA!B15,$Q$43:$Q$63,0)) | C44: 10 | D44: =INDEX($R$43:$R$63,MATCH(DATA!D15,$Q$43:$Q$63,0)) | E44: 25 | F44: =INDEX($R$43:$R$63,MATCH(DATA!F15,$Q$43:$Q$63,0)) | G44: 35 | H44: =INDEX($R$43:$R$63,MATCH(DATA!H15,$Q$43:$Q$63,0)) | I44: 50 | J44: =INDEX($R$43:$R$63,MATCH(DATA!J15,$Q$43:$Q$63,0)) | K44: 60 | L44: =INDEX($R$43:$R$63,MATCH(DATA!L15,$Q$43:$Q$63,0)) | M44: 75 | N44: =INDEX($R$43:$R$63,MATCH(DATA!N15,$Q$43:$Q$63,0)) | O44: 85 | P44: =INDEX($R$43:$R$63,MATCH(DATA!P15,$Q$43:$Q$63,0)) | Q44: 2 | R44: SC
A45: 0.5 | B45: =INDEX($R$43:$R$63,MATCH(DATA!B16,$Q$43:$Q$63,0)) | C45: 10.5 | D45: =INDEX($R$43:$R$63,MATCH(DATA!D16,$Q$43:$Q$63,0)) | E45: 25.5 | F45: =INDEX($R$43:$R$63,MATCH(DATA!F16,$Q$43:$Q$63,0)) | G45: 35.5 | H45: =INDEX($R$43:$R$63,MATCH(DATA!H16,$Q$43:$Q$63,0)) | I45: 50.5 | J45: =INDEX($R$43:$R$63,MATCH(DATA!J16,$Q$43:$Q$63,0)) | K45: 60.5 | L45: =INDEX($R$43:$R$63,MATCH(DATA!L16,$Q$43:$Q$63,0)) | M45: 75.5 | N45: =INDEX($R$43:$R$63,MATCH(DATA!N16,$Q$43:$Q$63,0)) | O45: 85.5 | P45: =INDEX($R$43:$R$63,MATCH(DATA!P16,$Q$43:$Q$63,0)) | Q45: 3 | R45: RKC
A46: 1 | B46: =INDEX($R$43:$R$63,MATCH(DATA!B17,$Q$43:$Q$63,0)) | C46: 11 | D46: =INDEX($R$43:$R$63,MATCH(DATA!D17,$Q$43:$Q$63,0)) | E46: 26 | F46: =INDEX($R$43:$R$63,MATCH(DATA!F17,$Q$43:$Q$63,0)) | G46: 36 | H46: =INDEX($R$43:$R$63,MATCH(DATA!H17,$Q$43:$Q$63,0)) | I46: 51 | J46: =INDEX($R$43:$R$63,MATCH(DATA!J17,$Q$43:$Q$63,0)) | K46: 61 | L46: =INDEX($R$43:$R$63,MATCH(DATA!L17,$Q$43:$Q$63,0)) | M46: 76 | N46: =INDEX($R$43:$R$63,MATCH(DATA!N17,$Q$43:$Q$63,0)) | O46: 86 | P46: =INDEX($R$43:$R$63,MATCH(DATA!P17,$Q$43:$Q$63,0)) | Q46: 4 | R46: NIA
A47: 1.5 | B47: =INDEX($R$43:$R$63,MATCH(DATA!B18,$Q$43:$Q$63,0)) | C47: 11.5 | D47: =INDEX($R$43:$R$63,MATCH(DATA!D18,$Q$43:$Q$63,0)) | E47: 26.5 | F47: =INDEX($R$43:$R$63,MATCH(DATA!F18,$Q$43:$Q$63,0)) | G47: 36.5 | H47: =INDEX($R$43:$R$63,MATCH(DATA!H18,$Q$43:$Q$63,0)) | I47: 51.5 | J47: =INDEX($R$43:$R$63,MATCH(DATA!J18,$Q$43:$Q$63,0)) | K47: 61.5 | L47: =INDEX($R$43:$R$63,MATCH(DATA!L18,$Q$43:$Q$63,0)) | M47: 76.5 | N47: =INDEX($R$43:$R$63,MATCH(DATA!N18,$Q$43:$Q$63,0)) | O47: 86.5 | P47: =INDEX($R$43:$R$63,MATCH(DATA!P18,$Q$43:$Q$63,0)) | Q47: 5 | R47: SP
A48: 2 | B48: =INDEX($R$43:$R$63,MATCH(DATA!B19,$Q$43:$Q$63,0)) | C48: 12 | D48: =INDEX($R$43:$R$63,MATCH(DATA!D19,$Q$43:$Q$63,0)) | E48: 27 | F48: =INDEX($R$43:$R$63,MATCH(DATA!F19,$Q$43:$Q$63,0)) | G48: 37 | H48: =INDEX($R$43:$R$63,MATCH(DATA!H19,$Q$43:$Q$63,0)) | I48: 52 | J48: =INDEX($R$43:$R$63,MATCH(DATA!J19,$Q$43:$Q$63,0)) | K48: 62 | L48: =INDEX($R$43:$R$63,MATCH(DATA!L19,$Q$43:$Q$63,0)) | M48: 77 | N48: =INDEX($R$43:$R$63,MATCH(DATA!N19,$Q$43:$Q$63,0)) | O48: 87 | P48: =INDEX($R$43:$R$63,MATCH(DATA!P19,$Q$43:$Q$63,0)) | Q48: 6 | R48: RC
A49: 2.5 | B49: =INDEX($R$43:$R$63,MATCH(DATA!B20,$Q$43:$Q$63,0)) | C49: 12.5 | D49: =INDEX($R$43:$R$63,MATCH(DATA!D20,$Q$43:$Q$63,0)) | E49: 27.5 | F49: =INDEX($R$43:$R$63,MATCH(DATA!F20,$Q$43:$Q$63,0)) | G49: 37.5 | H49: =INDEX($R$43:$R$63,MATCH(DATA!H20,$Q$43:$Q$63,0)) | I49: 52.5 | J49: =INDEX($R$43:$R$63,MATCH(DATA!J20,$Q$43:$Q$63,0)) | K49: 62.5 | L49: =INDEX($R$43:$R$63,MATCH(DATA!L20,$Q$43:$Q$63,0)) | M49: 77.5 | N49: =INDEX($R$43:$R$63,MATCH(DATA!N20,$Q$43:$Q$63,0)) | O49: 87.5 | P49: =INDEX($R$43:$R$63,MATCH(DATA!P20,$Q$43:$Q$63,0)) | Q49: 7 | R49: RB
A50: 3 | B50: =INDEX($R$43:$R$63,MATCH(DATA!B21,$Q$43:$Q$63,0)) | C50: 13 | D50: =INDEX($R$43:$R$63,MATCH(DATA!D21,$Q$43:$Q$63,0)) | E50: 28 | F50: =INDEX($R$43:$R$63,MATCH(DATA!F21,$Q$43:$Q$63,0)) | G50: 38 | H50: =INDEX($R$43:$R$63,MATCH(DATA!H21,$Q$43:$Q$63,0)) | I50: 53 | J50: =INDEX($R$43:$R$63,MATCH(DATA!J21,$Q$43:$Q$63,0)) | K50: 63 | L50: =INDEX($R$43:$R$63,MATCH(DATA!L21,$Q$43:$Q$63,0)) | M50: 78 | N50: =INDEX($R$43:$R$63,MATCH(DATA!N21,$Q$43:$Q$63,0)) | O50: 88 | P50: =INDEX($R$43:$R$63,MATCH(DATA!P21,$Q$43:$Q$63,0)) | Q50: 8 | R50: SD
A51: 3.5 | B51: =INDEX($R$43:$R$63,MATCH(DATA!B22,$Q$43:$Q$63,0)) | C51: 13.5 | D51: =INDEX($R$43:$R$63,MATCH(DATA!D22,$Q$43:$Q$63,0)) | E51: 28.5 | F51: =INDEX($R$43:$R$63,MATCH(DATA!F22,$Q$43:$Q$63,0)) | G51: 38.5 | H51: =INDEX($R$43:$R$63,MATCH(DATA!H22,$Q$43:$Q$63,0)) | I51: 53.5 | J51: =INDEX($R$43:$R$63,MATCH(DATA!J22,$Q$43:$Q$63,0)) | K51: 63.5 | L51: =INDEX($R$43:$R$63,MATCH(DATA!L22,$Q$43:$Q$63,0)) | M51: 78.5 | N51: =INDEX($R$43:$R$63,MATCH(DATA!N22,$Q$43:$Q$63,0)) | O51: 88.5 | P51: =INDEX($R$43:$R$63,MATCH(DATA!P22,$Q$43:$Q$63,0)) | Q51: 9 | R51: SI
A52: 4 | B52: =INDEX($R$43:$R$63,MATCH(DATA!B23,$Q$43:$Q$63,0)) | C52: 14 | D52: =INDEX($R$43:$R$63,MATCH(DATA!D23,$Q$43:$Q$63,0)) | E52: 29 | F52: =INDEX($R$43:$R$63,MATCH(DATA!F23,$Q$43:$Q$63,0)) | G52: 39 | H52: =INDEX($R$43:$R$63,MATCH(DATA!H23,$Q$43:$Q$63,0)) | I52: 54 | J52: =INDEX($R$43:$R$63,MATCH(DATA!J23,$Q$43:$Q$63,0)) | K52: 64 | L52: =INDEX($R$43:$R$63,MATCH(DATA!L23,$Q$43:$Q$63,0)) | M52: 79 | N52: =INDEX($R$43:$R$63,MATCH(DATA!N23,$Q$43:$Q$63,0)) | O52: 89 | P52: =INDEX($R$43:$R$63,MATCH(DATA!P23,$Q$43:$Q$63,0)) | Q52: 0 | R52: OT
A53: 4.5 | B53: =INDEX($R$43:$R$63,MATCH(DATA!B24,$Q$43:$Q$63,0)) | C53: 14.5 | D53: =INDEX($R$43:$R$63,MATCH(DATA!D24,$Q$43:$Q$63,0)) | E53: 29.5 | F53: =INDEX($R$43:$R$63,MATCH(DATA!F24,$Q$43:$Q$63,0)) | G53: 39.5 | H53: =INDEX($R$43:$R$63,MATCH(DATA!H24,$Q$43:$Q$63,0)) | I53: 54.5 | J53: =INDEX($R$43:$R$63,MATCH(DATA!J24,$Q$43:$Q$63,0)) | K53: 64.5 | L53: =INDEX($R$43:$R$63,MATCH(DATA!L24,$Q$43:$Q$63,0)) | M53: 79.5 | N53: =INDEX($R$43:$R$63,MATCH(DATA!N24,$Q$43:$Q$63,0)) | O53: 89.5 | P53: =INDEX($R$43:$R$63,MATCH(DATA!P24,$Q$43:$Q$63,0)) | Q53: a | R53: HC
A54: 5 | B54: =INDEX($R$43:$R$63,MATCH(DATA!B25,$Q$43:$Q$63,0)) | C54: 15 | D54: =INDEX($R$43:$R$63,MATCH(DATA!D25,$Q$43:$Q$63,0)) | E54: 30 | F54: =INDEX($R$43:$R$63,MATCH(DATA!F25,$Q$43:$Q$63,0)) | G54: 40 | H54: =INDEX($R$43:$R$63,MATCH(DATA!H25,$Q$43:$Q$63,0)) | I54: 55 | J54: =INDEX($R$43:$R$63,MATCH(DATA!J25,$Q$43:$Q$63,0)) | K54: 65 | L54: =INDEX($R$43:$R$63,MATCH(DATA!L25,$Q$43:$Q$63,0)) | M54: 80 | N54: =INDEX($R$43:$R$63,MATCH(DATA!N25,$Q$43:$Q$63,0)) | O54: 90 | P54: =INDEX($R$43:$R$63,MATCH(DATA!P25,$Q$43:$Q$63,0)) | Q54: b | R54: HC
A55: 5.5 | B55: =INDEX($R$43:$R$63,MATCH(DATA!B26,$Q$43:$Q$63,0)) | C55: 15.5 | D55: =INDEX($R$43:$R$63,MATCH(DATA!D26,$Q$43:$Q$63,0)) | E55: 30.5 | F55: =INDEX($R$43:$R$63,MATCH(DATA!F26,$Q$43:$Q$63,0)) | G55: 40.5 | H55: =INDEX($R$43:$R$63,MATCH(DATA!H26,$Q$43:$Q$63,0)) | I55: 55.5 | J55: =INDEX($R$43:$R$63,MATCH(DATA!J26,$Q$43:$Q$63,0)) | K55: 65.5 | L55: =INDEX($R$43:$R$63,MATCH(DATA!L26,$Q$43:$Q$63,0)) | M55: 80.5 | N55: =INDEX($R$43:$R$63,MATCH(DATA!N26,$Q$43:$Q$63,0)) | O55: 90.5 | P55: =INDEX($R$43:$R$63,MATCH(DATA!P26,$Q$43:$Q$63,0)) | Q55: c | R55: HC
A56: 6 | B56: =INDEX($R$43:$R$63,MATCH(DATA!B27,$Q$43:$Q$63,0)) | C56: 16 | D56: =INDEX($R$43:$R$63,MATCH(DATA!D27,$Q$43:$Q$63,0)) | E56: 31 | F56: =INDEX($R$43:$R$63,MATCH(DATA!F27,$Q$43:$Q$63,0)) | G56: 41 | H56: =INDEX($R$43:$R$63,MATCH(DATA!H27,$Q$43:$Q$63,0)) | I56: 56 | J56: =INDEX($R$43:$R$63,MATCH(DATA!J27,$Q$43:$Q$63,0)) | K56: 66 | L56: =INDEX($R$43:$R$63,MATCH(DATA!L27,$Q$43:$Q$63,0)) | M56: 81 | N56: =INDEX($R$43:$R$63,MATCH(DATA!N27,$Q$43:$Q$63,0)) | O56: 91 | P56: =INDEX($R$43:$R$63,MATCH(DATA!P27,$Q$43:$Q$63,0)) | Q56: 91 | R56: SI
A57: 6.5 | B57: =INDEX($R$43:$R$63,MATCH(DATA!B28,$Q$43:$Q$63,0)) | C57: 16.5 | D57: =INDEX($R$43:$R$63,MATCH(DATA!D28,$Q$43:$Q$63,0)) | E57: 31.5 | F57: =INDEX($R$43:$R$63,MATCH(DATA!F28,$Q$43:$Q$63,0)) | G57: 41.5 | H57: =INDEX($R$43:$R$63,MATCH(DATA!H28,$Q$43:$Q$63,0)) | I57: 56.5 | J57: =INDEX($R$43:$R$63,MATCH(DATA!J28,$Q$43:$Q$63,0)) | K57: 66.5 | L57: =INDEX($R$43:$R$63,MATCH(DATA!L28,$Q$43:$Q$63,0)) | M57: 81.5 | N57: =INDEX($R$43:$R$63,MATCH(DATA!N28,$Q$43:$Q$63,0)) | O57: 91.5 | P57: =INDEX($R$43:$R$63,MATCH(DATA!P28,$Q$43:$Q$63,0)) | Q57: 92 | R57: SI
A58: 7 | B58: =INDEX($R$43:$R$63,MATCH(DATA!B29,$Q$43:$Q$63,0)) | C58: 17 | D58: =INDEX($R$43:$R$63,MATCH(DATA!D29,$Q$43:$Q$63,0)) | E58: 32 | F58: =INDEX($R$43:$R$63,MATCH(DATA!F29,$Q$43:$Q$63,0)) | G58: 42 | H58: =INDEX($R$43:$R$63,MATCH(DATA!H29,$Q$43:$Q$63,0)) | I58: 57 | J58: =INDEX($R$43:$R$63,MATCH(DATA!J29,$Q$43:$Q$63,0)) | K58: 67 | L58: =INDEX($R$43:$R$63,MATCH(DATA!L29,$Q$43:$Q$63,0)) | M58: 82 | N58: =INDEX($R$43:$R$63,MATCH(DATA!N29,$Q$43:$Q$63,0)) | O58: 92 | P58: =INDEX($R$43:$R$63,MATCH(DATA!P29,$Q$43:$Q$63,0)) | Q58: 93 | R58: SI
A59: 7.5 | B59: =INDEX($R$43:$R$63,MATCH(DATA!B30,$Q$43:$Q$63,0)) | C59: 17.5 | D59: =INDEX($R$43:$R$63,MATCH(DATA!D30,$Q$43:$Q$63,0)) | E59: 32.5 | F59: =INDEX($R$43:$R$63,MATCH(DATA!F30,$Q$43:$Q$63,0)) | G59: 42.5 | H59: =INDEX($R$43:$R$63,MATCH(DATA!H30,$Q$43:$Q$63,0)) | I59: 57.5 | J59: =INDEX($R$43:$R$63,MATCH(DATA!J30,$Q$43:$Q$63,0)) | K59: 67.5 | L59: =INDEX($R$43:$R$63,MATCH(DATA!L30,$Q$43:$Q$63,0)) | M59: 82.5 | N59: =INDEX($R$43:$R$63,MATCH(DATA!N30,$Q$43:$Q$63,0)) | O59: 92.5 | P59: =INDEX($R$43:$R$63,MATCH(DATA!P30,$Q$43:$Q$63,0)) | Q59: 94 | R59: SI
A60: 8 | B60: =INDEX($R$43:$R$63,MATCH(DATA!B31,$Q$43:$Q$63,0)) | C60: 18 | D60: =INDEX($R$43:$R$63,MATCH(DATA!D31,$Q$43:$Q$63,0)) | E60: 33 | F60: =INDEX($R$43:$R$63,MATCH(DATA!F31,$Q$43:$Q$63,0)) | G60: 43 | H60: =INDEX($R$43:$R$63,MATCH(DATA!H31,$Q$43:$Q$63,0)) | I60: 58 | J60: =INDEX($R$43:$R$63,MATCH(DATA!J31,$Q$43:$Q$63,0)) | K60: 68 | L60: =INDEX($R$43:$R$63,MATCH(DATA!L31,$Q$43:$Q$63,0)) | M60: 83 | N60: =INDEX($R$43:$R$63,MATCH(DATA!N31,$Q$43:$Q$63,0)) | O60: 93 | P60: =INDEX($R$43:$R$63,MATCH(DATA!P31,$Q$43:$Q$63,0)) | Q60: 95 | R60: SI
A61: 8.5 | B61: =INDEX($R$43:$R$63,MATCH(DATA!B32,$Q$43:$Q$63,0)) | C61: 18.5 | D61: =INDEX($R$43:$R$63,MATCH(DATA!D32,$Q$43:$Q$63,0)) | E61: 33.5 | F61: =INDEX($R$43:$R$63,MATCH(DATA!F32,$Q$43:$Q$63,0)) | G61: 43.5 | H61: =INDEX($R$43:$R$63,MATCH(DATA!H32,$Q$43:$Q$63,0)) | I61: 58.5 | J61: =INDEX($R$43:$R$63,MATCH(DATA!J32,$Q$43:$Q$63,0)) | K61: 68.5 | L61: =INDEX($R$43:$R$63,MATCH(DATA!L32,$Q$43:$Q$63,0)) | M61: 83.5 | N61: =INDEX($R$43:$R$63,MATCH(DATA!N32,$Q$43:$Q$63,0)) | O61: 93.5 | P61: =INDEX($R$43:$R$63,MATCH(DATA!P32,$Q$43:$Q$63,0)) | Q61: 96 | R61: SI
A62: 9 | B62: =INDEX($R$43:$R$63,MATCH(DATA!B33,$Q$43:$Q$63,0)) | C62: 19 | D62: =INDEX($R$43:$R$63,MATCH(DATA!D33,$Q$43:$Q$63,0)) | E62: 34 | F62: =INDEX($R$43:$R$63,MATCH(DATA!F33,$Q$43:$Q$63,0)) | G62: 44 | H62: =INDEX($R$43:$R$63,MATCH(DATA!H33,$Q$43:$Q$63,0)) | I62: 59 | J62: =INDEX($R$43:$R$63,MATCH(DATA!J33,$Q$43:$Q$63,0)) | K62: 69 | L62: =INDEX($R$43:$R$63,MATCH(DATA!L33,$Q$43:$Q$63,0)) | M62: 84 | N62: =INDEX($R$43:$R$63,MATCH(DATA!N33,$Q$43:$Q$63,0)) | O62: 94 | P62: =INDEX($R$43:$R$63,MATCH(DATA!P33,$Q$43:$Q$63,0)) | Q62: 97 | R62: SI
A63: 9.5 | B63: =INDEX($R$43:$R$63,MATCH(DATA!B34,$Q$43:$Q$63,0)) | C63: 19.5 | D63: =INDEX($R$43:$R$63,MATCH(DATA!D34,$Q$43:$Q$63,0)) | E63: 34.5 | F63: =INDEX($R$43:$R$63,MATCH(DATA!F34,$Q$43:$Q$63,0)) | G63: 44.5 | H63: =INDEX($R$43:$R$63,MATCH(DATA!H34,$Q$43:$Q$63,0)) | I63: 59.5 | J63: =INDEX($R$43:$R$63,MATCH(DATA!J34,$Q$43:$Q$63,0)) | K63: 69.5 | L63: =INDEX($R$43:$R$63,MATCH(DATA!L34,$Q$43:$Q$63,0)) | M63: 84.5 | N63: =INDEX($R$43:$R$63,MATCH(DATA!N34,$Q$43:$Q$63,0)) | O63: 94.5 | P63: =INDEX($R$43:$R$63,MATCH(DATA!P34,$Q$43:$Q$63,0)) | Q63: 98 | R63: SI

Sheet 使用指引
A1: 如何使用 DATA 表單
A2: 1. 請將調查資料輸入指定表格中，若發現有些表格無法編輯，代表該區域不需編輯，已被鎖定
A4: 2. 底質請用數字輸入，數字前後不可以有空白或是其他符號
A6: 請再次確認您輸入的數值是否正確
A7: 3. 在每一個子樣區（共四區）分別有 40 個數值需要輸入，請確認每一欄的區間，以免輸錯欄位
A9: 4. 強烈建議輸入完成後第二次檢查，核對所有輸入資料
A11: 如果某區間的數值總數少於 40 個怎麼辦？（表單會自動計算，並顯示）
A12: 5. 您可能輸入錯誤的數值，例如：0 => 10，或是數字旁邊有空白鍵
A16: 如何在 GRAPHS 表單 分析 DATA 表單
A17: 1. 當您資料輸入完成，將會同步且自動的計算在 GRAPHS 表單
A18: 2. 請將這些檔案寄到 rcdata@reefcheck.org
A19: 2. 您只要將地點 潛點、日期、調查深度、替換掉圖上標題的藍色字體，並修改成黑色字體即可
... A56: For general stats, "Experimental Design and Data Analysis for Biologists", by G. P. Quinn and M. J. Keough, 2002, Cambridge University Press.

Sheet siteName
A1: 樣點名稱 | B1: Site Name
A2: 野柳 | B2: Yeliu
A3: 潮境保育區 | B3: Chaojing protected area
A4: 番仔澳 | B4: FanCai'ao
A5: 鼻頭角 | B5: Bitoujiao
A6: 龍洞1.5號 | B6: Longdong 1.5
A7: 龍洞4號-北 | B7: Longdong 4 North
A8: 龍洞4號-南 | B8: Longdong 4 South
A9: 和平島 | B9: Heping Island
A10: 合界 | B10: Hejie
A11: 後壁湖 | B11: Houbihu
A12: 石梯坪 | B12: Shitiping
... A42: 曙光礁 | B42: Shuguang Reef
