Workbook

Sheet 20260411
A2: 硬珊瑚
A3: 軟珊瑚
A4: 新死珊瑚
A5: 藻類
A6: 海綿
A7: 岩石
A8: 碎石
A9: 沙
A10: 泥
A11: 其他
A12: 活珊瑚覆蓋率 | B12: =SUM(B2,B3) | C12: =SUM(C2,C3)
A15: 硬珊瑚
A16: 軟珊瑚
A17: 新死珊瑚
A18: 藻類
A19: 海綿
A20: 岩石
A21: 碎石
A22: 沙
A23: 泥
A24: 其他
A28: 硬珊瑚型態
A29: A 空隙型
... A173: 一般垃圾

Sheet Summary (line)
A1: 5m
A2: HC | B2: 硬珊瑚
A3: SC | B3: 軟珊瑚
A4: RKC | B4: 新死珊瑚
A5: NIA | B5: 藻類
A6: SP | B6: 海綿
A7: RC | B7: 岩石
A8: RB | B8: 碎石
A9: SD | B9: 沙
A10: SI | B10: 泥沙
A11: OT | B11: 其他
B12: 活珊瑚覆蓋率 | C12: =C2+C3 | D12: =D2+D3 | E12: =E2+E3 | F12: =F2+F3 | G12: =G2+G3 | H12: =H2+H3 | I12: =I2+I3 | J12: =J2+J3 | ... Z12: =Z2+Z3
A13: 做
A14: 圖
A15: 用 | B15: 10m
A17: 5m
A18: HC | B18: 硬珊瑚
A19: SC | B19: 軟珊瑚
A20: RKC | B20: 新死珊瑚
A21: NIA | B21: 藻類
A22: SP | B22: 海綿
A23: RC | B23: 岩石
A24: RB | B24: 碎石
A25: SD | B25: 沙
A26: SI | B26: 泥沙
A27: OT | B27: 其他
N30: =(S12-T12)/S12*100
N31: =(S85-T85)/S85*100
A74: 10m | P74: =P1 | Q74: =Q1 | S74: =S1
A75: HC | B75: 硬珊瑚
A76: SC | B76: 軟珊瑚
A77: RKC | B77: 新死珊瑚
A78: NIA | B78: 藻類
A79: SP | B79: 海綿
A80: RC | B80: 岩石
A81: RB | B81: 碎石
A82: SD | B82: 沙
A83: SI | B83: 泥沙
A84: OT | B84: 其他
B85: 活珊瑚覆蓋率 | C85: =C75+C76 | D85: =D75+D76 | E85: =E75+E76 | F85: =F75+F76 | G85: =G75+G76 | H85: =H75+H76 | I85: =I75+I76 | J85: =J75+J76 | ... T85: =T75+T76 | V85: =V75+V76 | W85: =W75+W76 | X85: =X75+X76 | Y85: =Y75+Y76 | Z85: =Z75+Z76
...

Sheet Summary (fish)
A1: 5m | B1: 5m | R1: ='Summary (line)'!S1
A2: Butterflyfish | B2: 蝶魚
A3: Haemulidae | B3: 石鱸
A4: Snapper | B4: 笛鯛
A5: Barramundi cod | B5: 老鼠斑
A6: Grouper( ≥30cm) | B6: 石斑魚( ≥30cm)
A7: Grouper(<30cm) | B7: 石斑魚(<30cm)
A8: Humphead wrasse | B8: 蘇眉
A9: Bumphead parrot | B9: 隆頭鸚哥
A10: Parrotfish | B10: 鸚哥魚( ≥20cm)
A11: Moray eel | B11: 裸胸鯙
A13: 5m
A14: Butterflyfish | B14: 蝶魚
A15: Haemulidae | B15: 石鱸
A16: Snapper | B16: 笛鯛
A17: Barramundi cod | B17: 老鼠斑
A18: Grouper( ≥30cm) | B18: 石斑魚( ≥30cm)
A19: Grouper(<30cm) | B19: 石斑魚(<30cm)
A20: Humphead wrasse | B20: 蘇眉
A21: Bumphead parrot | B21: 隆頭鸚哥
A22: Parrotfish | B22: 鸚哥魚( ≥20cm)
A23: Moray eel | B23: 裸胸鯙
A68: 10m | R68: =R1
A69: Butterflyfish | B69: 蝶魚
A70: Haemulidae | B70: 石鱸
A71: Snapper | B71: 笛鯛
A72: Barramundi cod | B72: 老鼠斑
A73: Grouper( ≥30cm) | B73: 石斑魚( ≥30cm)
A74: Grouper(<30cm) | B74: 石斑魚(<30cm)
A75: Humphead wrasse | B75: 蘇眉
A76: Bumphead parrot | B76: 隆頭鸚哥
A77: Parrotfish | B77: 鸚哥魚( ≥20cm)
A78: Moray eel | B78: 裸胸鯙
A80: 10m
A81: Butterflyfish | B81: 蝶魚
A82: Haemulidae | B82: 石鱸
A83: Snapper | B83: 笛鯛
A84: Barramundi cod | B84: 老鼠斑
A85: Grouper( ≥30cm) | B85: 石斑魚( ≥30cm)
A86: Grouper(<30cm) | B86: 石斑魚(<30cm)
...

Sheet Summary (fish size)
A1: 5m | B1: 5m | C1: ='Summary (line)'!D1
A2: Butterflyfish ( ≥ 5cm) | B2: 蝴蝶魚 ( ≥ 5cm)
A3: Butterflyfish (<5cm) | B3: 蝴蝶魚 (<5cm)
A4: Haemulidae | B4: 石鱸
A5: Haemulidae (juv.) | B5: 石鱸幼魚 (妞妞魚)
A6: Snapper ( ≥ 20cm) | B6: 笛鯛 ( ≥ 20cm)
A7: Snapper (< 20cm) | B7: 小笛鯛 (< 20cm)
A8: Parrotfish ( ≥ 20cm) | B8: 鸚哥魚 ( ≥ 20cm)
A9: Parrotfish (<20 cm) | B9: 鸚哥魚 (<20 cm)
A10: Grouper( ≥30cm) | B10: 石斑 ( ≥ 30cm)
A11: Grouper(<30cm) | B11: 石斑 ( <30m)
A13: 5m
A14: Butterflyfish ( ≥ 5cm) | B14: 蝴蝶魚 ( ≥ 5cm)
A15: Butterflyfish (<5cm) | B15: 蝴蝶魚 (<5cm)
A16: Haemulidae | B16: 石鱸
A17: Haemulidae (juv.) | B17: 石鱸幼魚 (妞妞魚)
A18: Snapper ( ≥ 20cm) | B18: 笛鯛 ( ≥ 20cm)
A19: Snapper (< 20cm) | B19: 小笛鯛 (< 20cm)
A20: Parrotfish ( ≥ 20cm) | B20: 鸚哥魚 ( ≥ 20cm)
A21: Parrotfish (<20 cm) | B21: 鸚哥魚 (<20 cm)
A22: Grouper( ≥30cm) | B22: 石斑 ( ≥ 30cm)
A23: Grouper(<30cm) | B23: 石斑 ( <30m)
A68: 10m
A69: Butterflyfish ( ≥ 5cm) | B69: 蝴蝶魚 ( ≥ 5cm)
A70: Butterflyfish (<5cm) | B70: 蝴蝶魚 (<5cm)
A71: Haemulidae | B71: 石鱸
A72: Haemulidae (juv.) | B72: 石鱸幼魚 (妞妞魚)
A73: Snapper ( ≥ 20cm) | B73: 笛鯛 ( ≥ 20cm)
A74: Snapper (< 20cm) | B74: 小笛鯛 (< 20cm)
A75: Parrotfish ( ≥ 20cm) | B75: 鸚哥魚 ( ≥ 20cm)
A76: Parrotfish (<20 cm) | B76: 鸚哥魚 (<20 cm)
A77: Grouper( ≥30cm) | B77: 石斑 ( ≥ 30cm)
A78: Grouper(<30cm) | B78: 石斑 ( <30m)
A80: 10m
A81: Butterflyfish ( ≥ 5cm) | B81: 蝴蝶魚 ( ≥ 5cm)
A82: Butterflyfish (<5cm) | B82: 蝴蝶魚 (<5cm)
A83: Haemulidae | B83: 石鱸
A84: Haemulidae (juv.) | B84: 石鱸幼魚 (妞妞魚)
A85: Snapper ( ≥ 20cm) | B85: 笛鯛 ( ≥ 20cm)
A86: Snapper (< 20cm) | B86: 小笛鯛 (< 20cm)
...

Sheet Summary (Invertebrates)
A1: 5m | O1: ='Summary (fish)'!O1 | P1: ='Summary (fish)'!P1 | Q1: ='Summary (fish)'!Q1 | R1: ='Summary (fish)'!R1
A2: Banded coral shrimp | B2: 清潔蝦
A3: Diadema | B3: 魔鬼海膽
A4: Echinothrix | B4: 刺棘海膽
A5: Pencil urchin | B5: 鉛筆海膽
A6: Collector urchin | B6: 馬糞海膽
A7: Sea cucumber | B7: 海參
A8: Crown-of-thorns | B8: 棘冠海星
A9: Giant clam | B9: 硨磲貝
A10: Triton | B10: 大法螺
A11: Lobster | B11: 龍蝦
A14: 5m
A15: Banded coral shrimp | B15: 清潔蝦
A16: Diadema | B16: 魔鬼海膽
A17: Echinothrix | B17: 刺棘海膽
A18: Pencil urchin | B18: 鉛筆海膽
A19: Collector urchin | B19: 馬糞海膽
A20: Sea cucumber | B20: 海參
A21: Crown-of-thorns | B21: 棘冠海星
A22: Giant clam | B22: 硨磲貝
A23: Triton | B23: 大法螺
A24: Lobster | B24: 龍蝦
A67: 10m | O67: =O1 | P67: =P1 | Q67: ='Summary (fish)'!Q68 | R67: =R1
A68: Banded coral shrimp | B68: 清潔蝦
A69: Diadema | B69: 魔鬼海膽
A70: Echinothrix | B70: 刺棘海膽
A71: Pencil urchin | B71: 鉛筆海膽
A72: Collector urchin | B72: 馬糞海膽
A73: Sea cucumber | B73: 海參
A74: Crown-of-thorns | B74: 棘冠海星
A75: Giant clam | B75: 硨磲貝
A76: Triton | B76: 大法螺
A77: Lobster | B77: 龍蝦
A80: 10m
A81: Banded coral shrimp | B81: 清潔蝦
A82: Diadema | B82: 魔鬼海膽
A83: Echinothrix | B83: 刺棘海膽
A84: Pencil urchin | B84: 鉛筆海膽
A85: Collector urchin | B85: 馬糞海膽
A86: Sea cucumber | B86: 海參
...

Sheet Impacts
A1: 5米 | N1: ='Summary (Invertebrates)'!O1 | O1: ='Summary (Invertebrates)'!P1 | P1: ='Summary (Invertebrates)'!Q1 | Q1: ='Summary (Invertebrates)'!R1
A2: 珊瑚損害：船錨
A3: 珊瑚損害：炸魚
A4: 珊瑚損害：其他
A5: 漁業垃圾
A6: 一般垃圾
A9: 5米
A10: 珊瑚損害：船錨
A11: 珊瑚損害：炸魚
A12: 珊瑚損害：其他
A13: 漁業垃圾
A14: 一般垃圾
A51: 10m | N51: =N1 | O51: =O1 | P51: ='Summary (Invertebrates)'!Q67 | Q51: =Q1
A52: 珊瑚損害：船錨
A53: 珊瑚損害：炸魚
A54: 珊瑚損害：其他
A55: 漁業垃圾
A56: 一般垃圾
A59: 10m
A60: 珊瑚損害：船錨
A61: 珊瑚損害：炸魚
A62: 珊瑚損害：其他
A63: 漁業垃圾
A64: 一般垃圾
